for the cumulative graph I'm getting the following error.

Current code:
import matplotlib.pyplot as plt
import numpy as np

# Assuming `returns` is a DataFrame where each column is an asset class and each row is a time-point.
cumulative_returns = (1 + index_returns).cumprod()

events_dates = ['9/15/2008', '1/22/2015', '6/23/2016', '3/11/2020', '2/25/2022', '3/10/2023']

plt.figure(figsize=(12, 6))

# Plot cumulative returns for each asset
for asset in index_returns.columns:
    plt.plot(cumulative_returns.index, cumulative_returns[asset], label=asset)

# Highlight events with shaded regions
for date in events_dates:
    plt.axvline(x=date, color='gray', linestyle='--', alpha=0.5)

plt.legend()
plt.title('Cumulative Returns with Key Events Highlighted')
plt.ylabel('Cumulative Return')
plt.show()


Current error:
---------------------------------------------------------------------------
IndexError                                Traceback (most recent call last)
File C:\ProgramData\anaconda3\envs\blpapi\Lib\site-packages\matplotlib\axis.py:1732, in Axis.convert_units(self, x)
   1731 try:
-> 1732     ret = self.converter.convert(x, self.units, self)
   1733 except Exception as e:

File C:\ProgramData\anaconda3\envs\blpapi\Lib\site-packages\matplotlib\dates.py:1936, in _SwitchableDateConverter.convert(self, *args, **kwargs)
   1935 def convert(self, *args, **kwargs):
-> 1936     return self._get_converter().convert(*args, **kwargs)

File C:\ProgramData\anaconda3\envs\blpapi\Lib\site-packages\matplotlib\dates.py:1864, in DateConverter.convert(value, unit, axis)
   1858 """
   1859 If *value* is not already a number or sequence of numbers, convert it
   1860 with `date2num`.
   1861 
   1862 The *unit* and *axis* arguments are not used.
   1863 """
-> 1864 return date2num(value)

File C:\ProgramData\anaconda3\envs\blpapi\Lib\site-packages\matplotlib\dates.py:457, in date2num(d)
    456     return d
--> 457 tzi = getattr(d[0], 'tzinfo', None)
    458 if tzi is not None:
    459     # make datetime naive:

IndexError: too many indices for array: array is 0-dimensional, but 1 were indexed

The above exception was the direct cause of the following exception:

ConversionError                           Traceback (most recent call last)
Cell In[42], line 17
     15 # Highlight events with shaded regions
     16 for date in events_dates:
---> 17     plt.axvline(x=date, color='gray', linestyle='--', alpha=0.5)
     19 plt.legend()
     20 plt.title('Cumulative Returns with Key Events Highlighted')

File C:\ProgramData\anaconda3\envs\blpapi\Lib\site-packages\matplotlib\pyplot.py:2425, in axvline(x, ymin, ymax, **kwargs)
   2423 @_copy_docstring_and_deprecators(Axes.axvline)
   2424 def axvline(x=0, ymin=0, ymax=1, **kwargs):
-> 2425     return gca().axvline(x=x, ymin=ymin, ymax=ymax, **kwargs)

File C:\ProgramData\anaconda3\envs\blpapi\Lib\site-packages\matplotlib\axes\_axes.py:836, in Axes.axvline(self, x, ymin, ymax, **kwargs)
    833 xmin, xmax = self.get_xbound()
    835 # Strip away the units for comparison with non-unitized bounds.
--> 836 xx, = self._process_unit_info([("x", x)], kwargs)
    837 scalex = (xx < xmin) or (xx > xmax)
    839 trans = self.get_xaxis_transform(which='grid')

File C:\ProgramData\anaconda3\envs\blpapi\Lib\site-packages\matplotlib\axes\_base.py:2567, in _AxesBase._process_unit_info(self, datasets, kwargs, convert)
   2565             if dataset_axis_name == axis_name and data is not None:
   2566                 axis.update_units(data)
-> 2567 return [axis_map[axis_name].convert_units(data)
   2568         if convert and data is not None else data
   2569         for axis_name, data in datasets]

File C:\ProgramData\anaconda3\envs\blpapi\Lib\site-packages\matplotlib\axes\_base.py:2567, in <listcomp>(.0)
   2565             if dataset_axis_name == axis_name and data is not None:
   2566                 axis.update_units(data)
-> 2567 return [axis_map[axis_name].convert_units(data)
   2568         if convert and data is not None else data
   2569         for axis_name, data in datasets]

File C:\ProgramData\anaconda3\envs\blpapi\Lib\site-packages\matplotlib\axis.py:1734, in Axis.convert_units(self, x)
   1732     ret = self.converter.convert(x, self.units, self)
   1733 except Exception as e:
-> 1734     raise munits.ConversionError('Failed to convert value(s) to axis '
   1735                                  f'units: {x!r}') from e
   1736 return ret

ConversionError: Failed to convert value(s) to axis units: '9/15/2008'